Setting up a new session...
Traceback (most recent call last):
  File "/data/home/lumos/anaconda3/envs/pytorch/lib/python3.6/site-packages/urllib3/connection.py", line 170, in _new_conn
    (self._dns_host, self.port), self.timeout, **extra_kw
  File "/data/home/lumos/anaconda3/envs/pytorch/lib/python3.6/site-packages/urllib3/util/connection.py", line 96, in create_connection
    raise err
  File "/data/home/lumos/anaconda3/envs/pytorch/lib/python3.6/site-packages/urllib3/util/connection.py", line 86, in create_connection
    sock.connect(sa)
ConnectionRefusedError: [Errno 111] Connection refused

During handling of the above exception, another exception occurred:

Traceback (most recent call last):
  File "/data/home/lumos/anaconda3/envs/pytorch/lib/python3.6/site-packages/urllib3/connectionpool.py", line 706, in urlopen
    chunked=chunked,
  File "/data/home/lumos/anaconda3/envs/pytorch/lib/python3.6/site-packages/urllib3/connectionpool.py", line 394, in _make_request
    conn.request(method, url, **httplib_request_kw)
  File "/data/home/lumos/anaconda3/envs/pytorch/lib/python3.6/site-packages/urllib3/connection.py", line 234, in request
    super(HTTPConnection, self).request(method, url, body=body, headers=headers)
  File "/data/home/lumos/anaconda3/envs/pytorch/lib/python3.6/http/client.py", line 1287, in request
    self._send_request(method, url, body, headers, encode_chunked)
  File "/data/home/lumos/anaconda3/envs/pytorch/lib/python3.6/http/client.py", line 1333, in _send_request
    self.endheaders(body, encode_chunked=encode_chunked)
  File "/data/home/lumos/anaconda3/envs/pytorch/lib/python3.6/http/client.py", line 1282, in endheaders
    self._send_output(message_body, encode_chunked=encode_chunked)
  File "/data/home/lumos/anaconda3/envs/pytorch/lib/python3.6/http/client.py", line 1042, in _send_output
    self.send(msg)
  File "/data/home/lumos/anaconda3/envs/pytorch/lib/python3.6/http/client.py", line 980, in send
    self.connect()
  File "/data/home/lumos/anaconda3/envs/pytorch/lib/python3.6/site-packages/urllib3/connection.py", line 200, in connect
    conn = self._new_conn()
  File "/data/home/lumos/anaconda3/envs/pytorch/lib/python3.6/site-packages/urllib3/connection.py", line 182, in _new_conn
    self, "Failed to establish a new connection: %s" % e
urllib3.exceptions.NewConnectionError: <urllib3.connection.HTTPConnection object at 0x7fcb58a73128>: Failed to establish a new connection: [Errno 111] Connection refused

During handling of the above exception, another exception occurred:

Traceback (most recent call last):
  File "/data/home/lumos/anaconda3/envs/pytorch/lib/python3.6/site-packages/requests/adapters.py", line 449, in send
    timeout=timeout
  File "/data/home/lumos/anaconda3/envs/pytorch/lib/python3.6/site-packages/urllib3/connectionpool.py", line 756, in urlopen
    method, url, error=e, _pool=self, _stacktrace=sys.exc_info()[2]
  File "/data/home/lumos/anaconda3/envs/pytorch/lib/python3.6/site-packages/urllib3/util/retry.py", line 573, in increment
    raise MaxRetryError(_pool, url, error or ResponseError(cause))
urllib3.exceptions.MaxRetryError: HTTPConnectionPool(host='localhost', port=5565): Max retries exceeded with url: /env/check (Caused by NewConnectionError('<urllib3.connection.HTTPConnection object at 0x7fcb58a73128>: Failed to establish a new connection: [Errno 111] Connection refused',))

During handling of the above exception, another exception occurred:

Traceback (most recent call last):
  File "/data/home/lumos/anaconda3/envs/pytorch/lib/python3.6/site-packages/visdom/__init__.py", line 711, in _send
    data=json.dumps(msg),
  File "/data/home/lumos/anaconda3/envs/pytorch/lib/python3.6/site-packages/visdom/__init__.py", line 677, in _handle_post
    r = self.session.post(url, data=data)
  File "/data/home/lumos/anaconda3/envs/pytorch/lib/python3.6/site-packages/requests/sessions.py", line 590, in post
    return self.request('POST', url, data=data, json=json, **kwargs)
  File "/data/home/lumos/anaconda3/envs/pytorch/lib/python3.6/site-packages/requests/sessions.py", line 542, in request
    resp = self.send(prep, **send_kwargs)
  File "/data/home/lumos/anaconda3/envs/pytorch/lib/python3.6/site-packages/requests/sessions.py", line 655, in send
    r = adapter.send(request, **kwargs)
  File "/data/home/lumos/anaconda3/envs/pytorch/lib/python3.6/site-packages/requests/adapters.py", line 516, in send
    raise ConnectionError(e, request=request)
requests.exceptions.ConnectionError: HTTPConnectionPool(host='localhost', port=5565): Max retries exceeded with url: /env/check (Caused by NewConnectionError('<urllib3.connection.HTTPConnection object at 0x7fcb58a73128>: Failed to establish a new connection: [Errno 111] Connection refused',))
[Errno 113] No route to host
[Errno 113] No route to host
[Errno 113] No route to host
Visdom python client failed to establish socket to get messages from the server. This feature is optional and can be disabled by initializing Visdom with `use_incoming_socket=False`, which will prevent waiting for this request to timeout.
----------------- Options ---------------
               batch_size: 4                             	[default: 2]
                    beta1: 0.5                           
          checkpoints_dir: ./checkpoints                 
           continue_train: False                         
                crop_size: 512                           
                 dataroot: /data/home/lumos/pytorch-CycleGAN-and-pix2pix/datasets/New	[default: None]
             dataset_mode: usseg                         	[default: template]
                direction: AtoB                          
              display_env: check                         	[default: main]
             display_freq: 400                           
               display_id: 1                             
            display_ncols: 4                             
             display_port: 5565                          
           display_server: http://localhost              
          display_winsize: 256                           
                    epoch: latest                        
              epoch_count: 1                             
                 gan_mode: lsgan                         
                  gpu_ids: 0,1,2,3                       	[default: 0,1]
                init_gain: 0.02                          
                init_type: normal                        
                 input_nc: 1                             
                  isTrain: True                          	[default: None]
                 lambda_A: 10.0                          
                 lambda_B: 10.0                          
          lambda_identity: 0                             
                load_iter: 0                             	[default: 0]
                load_size: 512                           
                       lr: 0.0002                        
           lr_decay_iters: 50                            
                lr_policy: linear                        
         max_dataset_size: inf                           
                    model: usseg                         	[default: cycle_gan]
                 n_epochs: 100                           
           n_epochs_decay: 100                           
               n_layers_D: 3                             
                     name: check                         	[default: experiment_name]
                      ndf: 64                            
                     netD: basic                         
                     netG: resnet_9blocks                
       new_dataset_option: 1.0                           
                      ngf: 64                            
               no_dropout: True                          
                  no_flip: True                          	[default: False]
                  no_html: False                         
                     norm: instance                      
              num_threads: 4                             
                output_nc: 1                             
                    phase: train                         
                pool_size: 50                            
               preprocess: resize_and_crop               
               print_freq: 100                           
             save_by_iter: False                         
          save_epoch_freq: 5                             
         save_latest_freq: 5000                          
           serial_batches: False                         
                   suffix:                               
         update_html_freq: 1000                          
                  verbose: False                         
----------------- End -------------------
dataset [USSEGDataset] was created
The number of training images = 1620
initialize network with normal
initialize network with normal
initialize network with normal
initialize network with normal
model [USSEGModel] was created
---------- Networks initialized -------------
[Network G_A] Total number of parameters : 12.546 M
[Network G_B] Total number of parameters : 12.546 M
[Network D_A] Total number of parameters : 2.763 M
[Network D_B] Total number of parameters : 2.763 M
-----------------------------------------------
Exception in user code:
------------------------------------------------------------


Could not connect to Visdom server. 
 Trying to start a server....
Command: /data/home/lumos/anaconda3/envs/pytorch/bin/python -m visdom.server -p 5565 &>/dev/null &
create web directory ./checkpoints/check/web...
learning rate 0.0002000 -> 0.0002000
/data/home/lumos/anaconda3/envs/pytorch/lib/python3.6/site-packages/torch/optim/lr_scheduler.py:122: UserWarning: Detected call of `lr_scheduler.step()` before `optimizer.step()`. In PyTorch 1.1.0 and later, you should call them in the opposite order: `optimizer.step()` before `lr_scheduler.step()`.  Failure to do this will result in PyTorch skipping the first value of the learning rate schedule. See more details at https://pytorch.org/docs/stable/optim.html#how-to-adjust-learning-rate
  "https://pytorch.org/docs/stable/optim.html#how-to-adjust-learning-rate", UserWarning)
